[2024-09-11T15:36:19.135+0000] {local_task_job_runner.py:123} INFO - ::group::Pre task execution logs
[2024-09-11T15:36:19.146+0000] {taskinstance.py:2612} INFO - Dependencies all met for dep_context=non-requeueable deps ti=<TaskInstance: docker_operator_example.run_docker_container manual__2024-09-11T15:31:17.676917+00:00 [queued]>
[2024-09-11T15:36:19.150+0000] {taskinstance.py:2612} INFO - Dependencies all met for dep_context=requeueable deps ti=<TaskInstance: docker_operator_example.run_docker_container manual__2024-09-11T15:31:17.676917+00:00 [queued]>
[2024-09-11T15:36:19.150+0000] {taskinstance.py:2865} INFO - Starting attempt 2 of 2
[2024-09-11T15:36:19.156+0000] {taskinstance.py:2888} INFO - Executing <Task(DockerOperator): run_docker_container> on 2024-09-11 15:31:17.676917+00:00
[2024-09-11T15:36:19.159+0000] {standard_task_runner.py:72} INFO - Started process 468 to run task
[2024-09-11T15:36:19.161+0000] {standard_task_runner.py:104} INFO - Running: ['***', 'tasks', 'run', 'docker_operator_example', 'run_docker_container', 'manual__2024-09-11T15:31:17.676917+00:00', '--job-id', '76', '--raw', '--subdir', 'DAGS_FOLDER/my_dag.py', '--cfg-path', '/tmp/tmp_j9apfvp']
[2024-09-11T15:36:19.162+0000] {standard_task_runner.py:105} INFO - Job 76: Subtask run_docker_container
[2024-09-11T15:36:19.191+0000] {task_command.py:467} INFO - Running <TaskInstance: docker_operator_example.run_docker_container manual__2024-09-11T15:31:17.676917+00:00 [running]> on host 0a2ed70028ca
[2024-09-11T15:36:19.242+0000] {taskinstance.py:3131} INFO - Exporting env vars: AIRFLOW_CTX_DAG_OWNER='***' AIRFLOW_CTX_DAG_ID='docker_operator_example' AIRFLOW_CTX_TASK_ID='run_docker_container' AIRFLOW_CTX_EXECUTION_DATE='2024-09-11T15:31:17.676917+00:00' AIRFLOW_CTX_TRY_NUMBER='2' AIRFLOW_CTX_DAG_RUN_ID='manual__2024-09-11T15:31:17.676917+00:00'
[2024-09-11T15:36:19.242+0000] {taskinstance.py:731} INFO - ::endgroup::
[2024-09-11T15:36:19.258+0000] {docker.py:157} ERROR - Failed to establish connection to Docker host tcp://host.docker.internal:2375: Error while fetching server API version: HTTPConnectionPool(host='host.docker.internal', port=2375): Max retries exceeded with url: /version (Caused by NameResolutionError("<urllib3.connection.HTTPConnection object at 0x7bdddf1d9f50>: Failed to resolve 'host.docker.internal' ([Errno -2] Name or service not known)"))
[2024-09-11T15:36:19.263+0000] {taskinstance.py:3310} ERROR - Task failed with exception
Traceback (most recent call last):
  File "/home/airflow/.local/lib/python3.11/site-packages/airflow/models/taskinstance.py", line 767, in _execute_task
    result = _execute_callable(context=context, **execute_callable_kwargs)
             ^^^^^^^^^^^^^^^^^^^^^^^^^^^^^^^^^^^^^^^^^^^^^^^^^^^^^^^^^^^^^
  File "/home/airflow/.local/lib/python3.11/site-packages/airflow/models/taskinstance.py", line 733, in _execute_callable
    return ExecutionCallableRunner(
           ^^^^^^^^^^^^^^^^^^^^^^^^
  File "/home/airflow/.local/lib/python3.11/site-packages/airflow/utils/operator_helpers.py", line 252, in run
    return self.func(*args, **kwargs)
           ^^^^^^^^^^^^^^^^^^^^^^^^^^
  File "/home/airflow/.local/lib/python3.11/site-packages/airflow/models/baseoperator.py", line 406, in wrapper
    return func(self, *args, **kwargs)
           ^^^^^^^^^^^^^^^^^^^^^^^^^^^
  File "/home/airflow/.local/lib/python3.11/site-packages/airflow/providers/docker/operators/docker.py", line 495, in execute
    if self.force_pull or not self.cli.images(name=self.image):
                              ^^^^^^^^
  File "/home/airflow/.local/lib/python3.11/site-packages/airflow/providers/docker/operators/docker.py", line 363, in cli
    return self.hook.api_client
           ^^^^^^^^^^^^^^^^^^^^
  File "/usr/local/lib/python3.11/functools.py", line 1001, in __get__
    val = self.func(instance)
          ^^^^^^^^^^^^^^^^^^^
  File "/home/airflow/.local/lib/python3.11/site-packages/airflow/providers/docker/hooks/docker.py", line 161, in api_client
    raise AirflowException("Failed to establish connection to any given Docker hosts.")
airflow.exceptions.AirflowException: Failed to establish connection to any given Docker hosts.
[2024-09-11T15:36:19.265+0000] {taskinstance.py:1225} INFO - Marking task as FAILED. dag_id=docker_operator_example, task_id=run_docker_container, run_id=manual__2024-09-11T15:31:17.676917+00:00, execution_date=20240911T153117, start_date=20240911T153619, end_date=20240911T153619
[2024-09-11T15:36:19.270+0000] {taskinstance.py:340} INFO - ::group::Post task execution logs
[2024-09-11T15:36:19.270+0000] {standard_task_runner.py:124} ERROR - Failed to execute job 76 for task run_docker_container (Failed to establish connection to any given Docker hosts.; 468)
Traceback (most recent call last):
  File "/home/airflow/.local/lib/python3.11/site-packages/airflow/task/task_runner/standard_task_runner.py", line 117, in _start_by_fork
    ret = args.func(args, dag=self.dag)
          ^^^^^^^^^^^^^^^^^^^^^^^^^^^^^
  File "/home/airflow/.local/lib/python3.11/site-packages/airflow/cli/cli_config.py", line 49, in command
    return func(*args, **kwargs)
           ^^^^^^^^^^^^^^^^^^^^^
  File "/home/airflow/.local/lib/python3.11/site-packages/airflow/utils/cli.py", line 115, in wrapper
    return f(*args, **kwargs)
           ^^^^^^^^^^^^^^^^^^
  File "/home/airflow/.local/lib/python3.11/site-packages/airflow/cli/commands/task_command.py", line 483, in task_run
    task_return_code = _run_task_by_selected_method(args, _dag, ti)
                       ^^^^^^^^^^^^^^^^^^^^^^^^^^^^^^^^^^^^^^^^^^^^
  File "/home/airflow/.local/lib/python3.11/site-packages/airflow/cli/commands/task_command.py", line 256, in _run_task_by_selected_method
    return _run_raw_task(args, ti)
           ^^^^^^^^^^^^^^^^^^^^^^^
  File "/home/airflow/.local/lib/python3.11/site-packages/airflow/cli/commands/task_command.py", line 341, in _run_raw_task
    return ti._run_raw_task(
           ^^^^^^^^^^^^^^^^^
  File "/home/airflow/.local/lib/python3.11/site-packages/airflow/utils/session.py", line 97, in wrapper
    return func(*args, session=session, **kwargs)
           ^^^^^^^^^^^^^^^^^^^^^^^^^^^^^^^^^^^^^^
  File "/home/airflow/.local/lib/python3.11/site-packages/airflow/models/taskinstance.py", line 3004, in _run_raw_task
    return _run_raw_task(
           ^^^^^^^^^^^^^^
  File "/home/airflow/.local/lib/python3.11/site-packages/airflow/models/taskinstance.py", line 273, in _run_raw_task
    TaskInstance._execute_task_with_callbacks(
  File "/home/airflow/.local/lib/python3.11/site-packages/airflow/models/taskinstance.py", line 3158, in _execute_task_with_callbacks
    result = self._execute_task(context, task_orig)
             ^^^^^^^^^^^^^^^^^^^^^^^^^^^^^^^^^^^^^^
  File "/home/airflow/.local/lib/python3.11/site-packages/airflow/models/taskinstance.py", line 3182, in _execute_task
    return _execute_task(self, context, task_orig)
           ^^^^^^^^^^^^^^^^^^^^^^^^^^^^^^^^^^^^^^^
  File "/home/airflow/.local/lib/python3.11/site-packages/airflow/models/taskinstance.py", line 767, in _execute_task
    result = _execute_callable(context=context, **execute_callable_kwargs)
             ^^^^^^^^^^^^^^^^^^^^^^^^^^^^^^^^^^^^^^^^^^^^^^^^^^^^^^^^^^^^^
  File "/home/airflow/.local/lib/python3.11/site-packages/airflow/models/taskinstance.py", line 733, in _execute_callable
    return ExecutionCallableRunner(
           ^^^^^^^^^^^^^^^^^^^^^^^^
  File "/home/airflow/.local/lib/python3.11/site-packages/airflow/utils/operator_helpers.py", line 252, in run
    return self.func(*args, **kwargs)
           ^^^^^^^^^^^^^^^^^^^^^^^^^^
  File "/home/airflow/.local/lib/python3.11/site-packages/airflow/models/baseoperator.py", line 406, in wrapper
    return func(self, *args, **kwargs)
           ^^^^^^^^^^^^^^^^^^^^^^^^^^^
  File "/home/airflow/.local/lib/python3.11/site-packages/airflow/providers/docker/operators/docker.py", line 495, in execute
    if self.force_pull or not self.cli.images(name=self.image):
                              ^^^^^^^^
  File "/home/airflow/.local/lib/python3.11/site-packages/airflow/providers/docker/operators/docker.py", line 363, in cli
    return self.hook.api_client
           ^^^^^^^^^^^^^^^^^^^^
  File "/usr/local/lib/python3.11/functools.py", line 1001, in __get__
    val = self.func(instance)
          ^^^^^^^^^^^^^^^^^^^
  File "/home/airflow/.local/lib/python3.11/site-packages/airflow/providers/docker/hooks/docker.py", line 161, in api_client
    raise AirflowException("Failed to establish connection to any given Docker hosts.")
airflow.exceptions.AirflowException: Failed to establish connection to any given Docker hosts.
[2024-09-11T15:36:19.293+0000] {local_task_job_runner.py:266} INFO - Task exited with return code 1
[2024-09-11T15:36:19.304+0000] {taskinstance.py:3900} INFO - 0 downstream tasks scheduled from follow-on schedule check
[2024-09-11T15:36:19.305+0000] {local_task_job_runner.py:245} INFO - ::endgroup::
